Workbook

Sheet Screener
A1: Screener: one row per stock per trading day (join key ISIN + Date)
A2: Real data. Trading date: 01-Oct-2026. Generated 06-Oct-2026.
A4: Identity | G4: Red flags | J4: Weakness | L4: Price | Q4: Volume | Z4: Delivery | AG4: Activity | AH4: Deals | AJ4: F&O | AN4: Factors | AT4: Scans | AY4: Output | BB4: Price band | BC4: Surveillance watch | BE4: Corporate action | BF4: Buy checks | BH4: Returns | BN4: Trend | BV4: Selection
A5: Date | B5: Symbol | C5: ISIN | D5: Industry | E5: NSE Index | F5: Market cap (cr) | G5: Red flag | H5: Red flag reason | I5: No intraday | J5: Weakness list | K5: Weakness reason | L5: Close | M5: Chg % (vs previous close) | N5: Rank Gainer/Loser (of universe) | O5: NSE Top 20 Gainers/Losers | P5: 52-wk status | Q5: Volume (lakh) | R5: Avg volume, 20-day (lakh) | S5: Volume vs 20-day avg (x) | T5: Volume vs 50-day avg (x) | U5: Volume vs 100-day avg (x) | V5: Volume build-up (x) | W5: Volume active days (of 20) | X5: Rank volume spike | Y5: NSE Most Active (Top 20) | Z5: Delivery % | AA5: Delivery % vs 20-day avg (x) | AB5: Delivery % vs 50-day avg (x) | AC5: Delivered qty vs 20-day avg (x) | AD5: Delivered qty vs 50-day avg (x) | AE5: Delivered qty vs 100-day avg (x) | AF5: Delivery share trend (x) | AG5: Activity stage | AH5: Bulk deal net qty | AI5: Block deal buy qty | AJ5: Traded in F&O | AK5: % chg in open interest | AL5: OI signal | AM5: Rank F&O activity | AN5: Momentum indices | AO5: Momentum index count (of 7) | AP5: Own momentum score | AQ5: Own momentum percentile (of universe) | AR5: FPI 150 member | AS5: Industry strength vs Nifty, 20-day (%) | AT5: Breakout | AU5: Accumulation | AV5: Institutional buying | AW5: Long buildup | AX5: Momentum leader | AY5: Buy scans passed (count) | AZ5: Scans passed (buy-side) | BA5: Why ranked here | BB5: Price band hit today | BC5: Surveillance watch | BD5: Surveillance watch reason | BE5: Split/bonus (recent) | BF5: Liquidity (>= 1 lakh) | BG5: Market cap (> 500 cr) | BH5: % change from 52-week high/low | BI5: Return 1 week (%) | BJ5: Return 1 month (%) | BK5: Return 3 months (%) | BL5: Return 6 months (%) | BM5: Return 12 months (%) | BN5: Close vs EMA 20 (%) | BO5: Close vs EMA 50 (%) | BP5: Close vs EMA 100 (%) | BQ5: Close vs EMA 200 (%) | BR5: EMA trend | BS5: EMA 20/50 cross | BT5: RSI (9) | BU5: EMA pullback bounce | BV5: Selection score (of 10) | BW5: Rank buy scans
A6: 46296 | B6: RELIANCE | C6: INE002A01018 | D6: Oil Gas & Consumable Fuels | E6: Nifty 50 | F6: 1580195 | G6: N | I6: N | J6: =IF(K6="","N","Y") | K6: =_xlfn.TEXTJOIN("; ",TRUE,IF(P6="52-wk low","52-wk low",""),IF(AND(AD6>=Settings!$B$12,M6<0),"Distribution",""),IF(AND(AJ6="Y",M6<0,AK6<-Settings!$B$13),"Long unwinding",""),IF(AND(AJ6="Y",M6<0,AK6>Settings!$B$13),"Short buildup","")) | L6: 1167.7 | M6: -1.63 | N6: 1420 | O6: None | P6: 52-wk low | Q6: 167.71 | R6: 123.35 | S6: 1.38 | T6: 1.47 | U6: 1.24 | V6: 0.91 | W6: 6 | X6: 220 | Y6: By value | Z6: 61.24 | AA6: 0.97 | AB6: 1 | AC6: 1.32 | AD6: 1.44 | AE6: 1.34 | AF6: 1.12 | AG6: Normal | AH6: 0 | AI6: 0 | AJ6: Y | AK6: 1.6 | AL6: Short buildup | AM6: 5 | AN6: None | AO6: 0 | AP6: 0.52 | AQ6: 8 | AR6: Y | AS6: 2.69 | AT6: =IF(AND(P6="52-wk high",T6>=Settings!$B$7),"Y","N") | AU6: =IF(AND(AD6>=Settings!$B$8,M6>0),"Y","N") | AV6: =IF(OR(AH6>Settings!$B$9,AI6>Settings!$B$9),"Y","N") | AW6: =IF(AJ6<>"Y","n/a",IF(AND(M6>0,AK6>Settings!$B$10),"Y","N")) | AX6: =IF(AO6>=Settings!$B$11,"Y","N") | AY6: =(AT6="Y")+(AU6="Y")+(AV6="Y")+(AW6="Y")+(AX6="Y") | AZ6: =IF(AY6=0,"None",_xlfn.TEXTJOIN(", ",TRUE(),IF(AT6="Y","Breakout",""),IF(AU6="Y","Accumulation",""),IF(AV6="Y","Institutional buying",""),IF(AW6="Y","Long buildup",""),IF(AX6="Y","Momentum leader",""))) | BA6: =IF(BW6="","","Passes "&AY6&" of 5 buy-side scans"&IF(G6="Y","; RED FLAG: filter out using Red flag column","")) | BB6: None | BC6: N | BF6: =IF(R6*100000>=Settings!$B$5,"Y","N") | BG6: =IF(F6>Settings!$B$6,"Y","N") | BH6: -27.55 | BI6: -4.22 | BJ6: -10.79 | BK6: -10.73 | BL6: -14.72 | BM6: -14.69 | BN6: -5.4 | BO6: -7.98 | BP6: -10.13 | BQ6: -12.67 | BR6: Stacked down | BS6: None | BT6: 23.8 | BU6: N | BV6: =IF(OR(BF6<>"Y",BG6<>"Y"),"",(AND(ISNUMBER(BQ6),BQ6>0))+(BR6="Stacked up")+(AND(ISNUMBER(BH6),BH6>=-Settings!$B$17))+(AND(ISNUMBER(BK6),ISNUMBER(BM6),BK6>0,BM6>0))+(AND(ISNUMBER(AQ6),AQ6>=Settings!$B$18))+(AND(ISNUMBER(BT6),BT6>=Settings!$B$19,BT6<=Settings!$B$20))+(AND(ISNUMBER(AS6),AS6>0))+(AND(ISNUMBER(T6),ISNUMBER(M6),T6>=Settings!$B$21,M6>0))+(AND(ISNUMBER(AD6),ISNUMBER(M6),AD6>=Settings!$B$22,M6>0))+(AY6>=1)) | BW6: =IF(OR(AY6=0,BF6<>"Y",BG6<>"Y"),"",1+SUMPRODUCT(($A$6:$A$2604=A6)*($AY$6:$AY$2604>0)*($BF$6:$BF$2604="Y")*($BG$6:$BG$2604="Y")*(($AY$6:$AY$2604>AY6)+($AY$6:$AY$2604=AY6)*($AD$6:$AD$2604>AD6))))
A7: 46296 | B7: HDFCBANK | C7: INE040A01034 | D7: Financial Services | E7: Nifty 50 | F7: 1111852 | G7: N | I7: N | J7: =IF(K7="","N","Y") | K7: =_xlfn.TEXTJOIN("; ",TRUE,IF(P7="52-wk low","52-wk low",""),IF(AND(AD7>=Settings!$B$12,M7<0),"Distribution",""),IF(AND(AJ7="Y",M7<0,AK7<-Settings!$B$13),"Long unwinding",""),IF(AND(AJ7="Y",M7<0,AK7>Settings!$B$13),"Short buildup","")) | L7: 721.2 | M7: 1.76 | N7: 216 | O7: None | P7: None | Q7: 373.9 | R7: 297.8 | S7: 1.26 | T7: 1.29 | U7: 1.13 | V7: 0.9 | W7: 8 | X7: 258 | Y7: Both | Z7: 63.31 | AA7: 1.02 | AB7: 1.01 | AC7: 1.28 | AD7: 1.32 | AE7: 1.2 | AF7: 1.04 | AG7: Normal | AH7: 0 | AI7: 0 | AJ7: Y | AK7: -1.28 | AL7: Short covering | AM7: 3 | AN7: None | AO7: 0 | AP7: 0.55 | AQ7: 11 | AR7: Y | AS7: 0.6 | AT7: =IF(AND(P7="52-wk high",T7>=Settings!$B$7),"Y","N") | AU7: =IF(AND(AD7>=Settings!$B$8,M7>0),"Y","N") | AV7: =IF(OR(AH7>Settings!$B$9,AI7>Settings!$B$9),"Y","N") | AW7: =IF(AJ7<>"Y","n/a",IF(AND(M7>0,AK7>Settings!$B$10),"Y","N")) | AX7: =IF(AO7>=Settings!$B$11,"Y","N") | AY7: =(AT7="Y")+(AU7="Y")+(AV7="Y")+(AW7="Y")+(AX7="Y") | AZ7: =IF(AY7=0,"None",_xlfn.TEXTJOIN(", ",TRUE(),IF(AT7="Y","Breakout",""),IF(AU7="Y","Accumulation",""),IF(AV7="Y","Institutional buying",""),IF(AW7="Y","Long buildup",""),IF(AX7="Y","Momentum leader",""))) | BA7: =IF(BW7="","","Passes "&AY7&" of 5 buy-side scans"&IF(G7="Y","; RED FLAG: filter out using Red flag column","")) | BB7: None | BC7: N | BF7: =IF(R7*100000>=Settings!$B$5,"Y","N") | BG7: =IF(F7>Settings!$B$6,"Y","N") | BH7: -29.33 | BI7: -1.06 | BJ7: 1.31 | BK7: -9.41 | BL7: -2.84 | BM7: -25.28 | BN7: -0.08 | BO7: -1.41 | BP7: -4.58 | BQ7: -10.11 | BR7: Stacked down | BS7: None | BT7: 49.6 | BU7: N | BV7: =IF(OR(BF7<>"Y",BG7<>"Y"),"",(AND(ISNUMBER(BQ7),BQ7>0))+(BR7="Stacked up")+(AND(ISNUMBER(BH7),BH7>=-Settings!$B$17))+(AND(ISNUMBER(BK7),ISNUMBER(BM7),BK7>0,BM7>0))+(AND(ISNUMBER(AQ7),AQ7>=Settings!$B$18))+(AND(ISNUMBER(BT7),BT7>=Settings!$B$19,BT7<=Settings!$B$20))+(AND(ISNUMBER(AS7),AS7>0))+(AND(ISNUMBER(T7),ISNUMBER(M7),T7>=Settings!$B$21,M7>0))+(AND(ISNUMBER(AD7),ISNUMBER(M7),AD7>=Settings!$B$22,M7>0))+(AY7>=1)) | BW7: =IF(OR(AY7=0,BF7<>"Y",BG7<>"Y"),"",1+SUMPRODUCT(($A$6:$A$2604=A7)*($AY$6:$AY$2604>0)*($BF$6:$BF$2604="Y")*($BG$6:$BG$2604="Y")*(($AY$6:$AY$2604>AY7)+($AY$6:$AY$2604=AY7)*($AD$6:$AD$2604>AD7))))
A8: 46296 | B8: BHARTIARTL | C8: INE397D01024 | D8: Telecommunication | E8: Nifty 50 | F8: 1086534 | G8: N | I8: N | J8: =IF(K8="","N","Y") | K8: =_xlfn.TEXTJOIN("; ",TRUE,IF(P8="52-wk low","52-wk low",""),IF(AND(AD8>=Settings!$B$12,M8<0),"Distribution",""),IF(AND(AJ8="Y",M8<0,AK8<-Settings!$B$13),"Long unwinding",""),IF(AND(AJ8="Y",M8<0,AK8>Settings!$B$13),"Short buildup","")) | L8: 1741.1 | M8: -0.9 | N8: 987 | O8: None | P8: 52-wk low | Q8: 56.1 | R8: 56.21 | S8: 1.01 | T8: 0.89 | U8: 0.75 | V8: 0.77 | W8: 4 | Y8: By value | Z8: 63.89 | AA8: 0.91 | AB8: 0.93 | AC8: 0.9 | AD8: 0.83 | AE8: 0.73 | AF8: 1.08 | AG8: Normal | AH8: 0 | AI8: 0 | AJ8: Y | AK8: -0.69 | AL8: Long unwinding | AM8: 20 | AN8: None | AO8: 0 | AP8: 0.7 | AQ8: 38 | AR8: Y | AS8: 2.57 | AT8: =IF(AND(P8="52-wk high",T8>=Settings!$B$7),"Y","N") | AU8: =IF(AND(AD8>=Settings!$B$8,M8>0),"Y","N") | AV8: =IF(OR(AH8>Settings!$B$9,AI8>Settings!$B$9),"Y","N") | AW8: =IF(AJ8<>"Y","n/a",IF(AND(M8>0,AK8>Settings!$B$10),"Y","N")) | AX8: =IF(AO8>=Settings!$B$11,"Y","N") | AY8: =(AT8="Y")+(AU8="Y")+(AV8="Y")+(AW8="Y")+(AX8="Y") | AZ8: =IF(AY8=0,"None",_xlfn.TEXTJOIN(", ",TRUE(),IF(AT8="Y","Breakout",""),IF(AU8="Y","Accumulation",""),IF(AV8="Y","Institutional buying",""),IF(AW8="Y","Long buildup",""),IF(AX8="Y","Momentum leader",""))) | BA8: =IF(BW8="","","Passes "&AY8&" of 5 buy-side scans"&IF(G8="Y","; RED FLAG: filter out using Red flag column","")) | BB8: None | BC8: N | BF8: =IF(R8*100000>=Settings!$B$5,"Y","N") | BG8: =IF(F8>Settings!$B$6,"Y","N") | BH8: -19.93 | BI8: -3.05 | BJ8: -7.25 | BK8: -6.94 | BL8: -2.29 | BM8: -6.77 | BN8: -4.13 | BO8: -6.23 | BP8: -7.22 | BQ8: -8.34 | BR8: Stacked down | BS8: None | BT8: 27.4 | BU8: N | BV8: =IF(OR(BF8<>"Y",BG8<>"Y"),"",(AND(ISNUMBER(BQ8),BQ8>0))+(BR8="Stacked up")+(AND(ISNUMBER(BH8),BH8>=-Settings!$B$17))+(AND(ISNUMBER(BK8),ISNUMBER(BM8),BK8>0,BM8>0))+(AND(ISNUMBER(AQ8),AQ8>=Settings!$B$18))+(AND(ISNUMBER(BT8),BT8>=Settings!$B$19,BT8<=Settings!$B$20))+(AND(ISNUMBER(AS8),AS8>0))+(AND(ISNUMBER(T8),ISNUMBER(M8),T8>=Settings!$B$21,M8>0))+(AND(ISNUMBER(AD8),ISNUMBER(M8),AD8>=Settings!$B$22,M8>0))+(AY8>=1)) | BW8: =IF(OR(AY8=0,BF8<>"Y",BG8<>"Y"),"",1+SUMPRODUCT(($A$6:$A$2604=A8)*($AY$6:$AY$2604>0)*($BF$6:$BF$2604="Y")*($BG$6:$BG$2604="Y")*(($AY$6:$AY$2604>AY8)+($AY$6:$AY$2604=AY8)*($AD$6:$AD$2604>AD8))))
A9: 46296 | B9: ICICIBANK | C9: INE090A01021 | D9: Financial Services | E9: Nifty 50 | F9: 940809 | G9: N | I9: N | J9: =IF(K9="","N","Y") | K9: =_xlfn.TEXTJOIN("; ",TRUE,IF(P9="52-wk low","52-wk low",""),IF(AND(AD9>=Settings!$B$12,M9<0),"Distribution",""),IF(AND(AJ9="Y",M9<0,AK9<-Settings!$B$13),"Long unwinding",""),IF(AND(AJ9="Y",M9<0,AK9>Settings!$B$13),"Short buildup","")) | L9: 1310.6 | M9: -0.84 | N9: 951 | O9: None | P9: None | Q9: 131.63 | R9: 94.58 | S9: 1.43 | T9: 1.34 | U9: 1.03 | V9: 0.74 | W9: 4 | X9: 238 | Y9: By value | Z9: 57.07 | AA9: 0.88 | AB9: 0.92 | AC9: 1.25 | AD9: 1.23 | AE9: 0.97 | AF9: 1.07 | AG9: Normal | AH9: 0 | AI9: 0 | AJ9: Y | AK9: 0.06 | AL9: Short buildup | AM9: 6 | AN9: None | AO9: 0 | AP9: 0.91 | AQ9: 57 | AR9: Y | AS9: 0.6 | AT9: =IF(AND(P9="52-wk high",T9>=Settings!$B$7),"Y","N") | AU9: =IF(AND(AD9>=Settings!$B$8,M9>0),"Y","N") | AV9: =IF(OR(AH9>Settings!$B$9,AI9>Settings!$B$9),"Y","N") | AW9: =IF(AJ9<>"Y","n/a",IF(AND(M9>0,AK9>Settings!$B$10),"Y","N")) | AX9: =IF(AO9>=Settings!$B$11,"Y","N") | AY9: =(AT9="Y")+(AU9="Y")+(AV9="Y")+(AW9="Y")+(AX9="Y") | AZ9: =IF(AY9=0,"None",_xlfn.TEXTJOIN(", ",TRUE(),IF(AT9="Y","Breakout",""),IF(AU9="Y","Accumulation",""),IF(AV9="Y","Institutional buying",""),IF(AW9="Y","Long buildup",""),IF(AX9="Y","Momentum leader",""))) | BA9: =IF(BW9="","","Passes "&AY9&" of 5 buy-side scans"&IF(G9="Y","; RED FLAG: filter out using Red flag column","")) | BB9: None | BC9: N | BF9: =IF(R9*100000>=Settings!$B$5,"Y","N") | BG9: =IF(F9>Settings!$B$6,"Y","N") | BH9: -11.45 | BI9: -1.79 | BJ9: -8.86 | BK9: -5.02 | BL9: 8.07 | BM9: -4.48 | BN9: -2.89 | BO9: -4.73 | BP9: -4.51 | BQ9: -4.01 | BR9: Mixed | BS9: None | BT9: 33.5 | BU9: N | BV9: =IF(OR(BF9<>"Y",BG9<>"Y"),"",(AND(ISNUMBER(BQ9),BQ9>0))+(BR9="Stacked up")+(AND(ISNUMBER(BH9),BH9>=-Settings!$B$17))+(AND(ISNUMBER(BK9),ISNUMBER(BM9),BK9>0,BM9>0))+(AND(ISNUMBER(AQ9),AQ9>=Settings!$B$18))+(AND(ISNUMBER(BT9),BT9>=Settings!$B$19,BT9<=Settings!$B$20))+(AND(ISNUMBER(AS9),AS9>0))+(AND(ISNUMBER(T9),ISNUMBER(M9),T9>=Settings!$B$21,M9>0))+(AND(ISNUMBER(AD9),ISNUMBER(M9),AD9>=Settings!$B$22,M9>0))+(AY9>=1)) | BW9: =IF(OR(AY9=0,BF9<>"Y",BG9<>"Y"),"",1+SUMPRODUCT(($A$6:$A$2604=A9)*($AY$6:$AY$2604>0)*($BF$6:$BF$2604="Y")*($BG$6:$BG$2604="Y")*(($AY$6:$AY$2604>AY9)+($AY$6:$AY$2604=AY9)*($AD$6:$AD$2604>AD9))))
A10: 46296 | B10: SBIN | C10: INE062A01020 | D10: Financial Services | E10: Nifty 50 | F10: 880707 | G10: N | I10: N | J10: =IF(K10="","N","Y") | K10: =_xlfn.TEXTJOIN("; ",TRUE,IF(P10="52-wk low","52-wk low",""),IF(AND(AD10>=Settings!$B$12,M10<0),"Distribution",""),IF(AND(AJ10="Y",M10<0,AK10<-Settings!$B$13),"Long unwinding",""),IF(AND(AJ10="Y",M10<0,AK10>Settings!$B$13),"Short buildup","")) | L10: 954.1 | M10: -0.56 | N10: 816 | O10: None | P10: None | Q10: 73.9 | R10: 84.23 | S10: 0.85 | T10: 0.81 | U10: 0.63 | V10: 0.75 | W10: 2 | Y10: None | Z10: 50.73 | AA10: 0.88 | AB10: 0.93 | AC10: 0.7 | AD10: 0.75 | AE10: 0.6 | AF10: 1.12 | AG10: Normal | AH10: 0 | AI10: 0 | AJ10: Y | AK10: -0.09 | AL10: Long unwinding | AM10: 19 | AN10: None | AO10: 0 | AP10: 0.86 | AQ10: 54 | AR10: Y | AS10: 0.6 | AT10: =IF(AND(P10="52-wk high",T10>=Settings!$B$7),"Y","N") | AU10: =IF(AND(AD10>=Settings!$B$8,M10>0),"Y","N") | AV10: =IF(OR(AH10>Settings!$B$9,AI10>Settings!$B$9),"Y","N") | AW10: =IF(AJ10<>"Y","n/a",IF(AND(M10>0,AK10>Settings!$B$10),"Y","N")) | AX10: =IF(AO10>=Settings!$B$11,"Y","N") | AY10: =(AT10="Y")+(AU10="Y")+(AV10="Y")+(AW10="Y")+(AX10="Y") | AZ10: =IF(AY10=0,"None",_xlfn.TEXTJOIN(", ",TRUE(),IF(AT10="Y","Breakout",""),IF(AU10="Y","Accumulation",""),IF(AV10="Y","Institutional buying",""),IF(AW10="Y","Long buildup",""),IF(AX10="Y","Momentum leader",""))) | BA10: =IF(BW10="","","Passes "&AY10&" of 5 buy-side scans"&IF(G10="Y","; RED FLAG: filter out using Red flag column","")) | BB10: None | BC10: N | BF10: =IF(R10*100000>=Settings!$B$5,"Y","N") | BG10: =IF(F10>Settings!$B$6,"Y","N") | BH10: -22.73 | BI10: -2.49 | BJ10: -7.77 | BK10: -8.91 | BL10: -6.26 | BM10: 10.42 | BN10: -3.52 | BO10: -5.63 | BP10: -6.55 | BQ10: -5.81 | BR10: Mixed | BS10: None | BT10: 28.5 | BU10: N | BV10: =IF(OR(BF10<>"Y",BG10<>"Y"),"",(AND(ISNUMBER(BQ10),BQ10>0))+(BR10="Stacked up")+(AND(ISNUMBER(BH10),BH10>=-Settings!$B$17))+(AND(ISNUMBER(BK10),ISNUMBER(BM10),BK10>0,BM10>0))+(AND(ISNUMBER(AQ10),AQ10>=Settings!$B$18))+(AND(ISNUMBER(BT10),BT10>=Settings!$B$19,BT10<=Settings!$B$20))+(AND(ISNUMBER(AS10),AS10>0))+(AND(ISNUMBER(T10),ISNUMBER(M10),T10>=Settings!$B$21,M10>0))+(AND(ISNUMBER(AD10),ISNUMBER(M10),AD10>=Settings!$B$22,M10>0))+(AY10>=1)) | BW10: =IF(OR(AY10=0,BF10<>"Y",BG10<>"Y"),"",1+SUMPRODUCT(($A$6:$A$2604=A10)*($AY$6:$AY$2604>0)*($BF$6:$BF$2604="Y")*($BG$6:$BG$2604="Y")*(($AY$6:$AY$2604>AY10)+($AY$6:$AY$2604=AY10)*($AD$6:$AD$2604>AD10))))
A11: 46296 | B11: TCS | C11: INE467B01029 | D11: Information Technology | E11: Nifty 50 | F11: 750753 | G11: N | I11: N | J11: =IF(K11="","N","Y") | K11: =_xlfn.TEXTJOIN("; ",TRUE,IF(P11="52-wk low","52-wk low",""),IF(AND(AD11>=Settings!$B$12,M11<0),"Distribution",""),IF(AND(AJ11="Y",M11<0,AK11<-Settings!$B$13),"Long unwinding",""),IF(AND(AJ11="Y",M11<0,AK11>Settings!$B$13),"Short buildup","")) | L11: 2075 | M11: 1.19 | N11: 300 | O11: None | P11: None | Q11: 34.29 | R11: 31.51 | S11: 1.1 | T11: 1.08 | U11: 0.8 | V11: 0.74 | W11: 3 | Y11: None | Z11: 54.9 | AA11: 1.1 | AB11: 1.12 | AC11: 1.2 | AD11: 1.2 | AE11: 0.9 | AF11: 1.04 | AG11: Normal | AH11: 0 | AI11: 0 | AJ11: Y | AK11: 1.83 | AL11: Long buildup | AM11: 14 | AN11: None | AO11: 0 | AP11: 0.52 | AQ11: 7 | AR11: Y | AS11: -0.75 | AT11: =IF(AND(P11="52-wk high",T11>=Settings!$B$7),"Y","N") | AU11: =IF(AND(AD11>=Settings!$B$8,M11>0),"Y","N") | AV11: =IF(OR(AH11>Settings!$B$9,AI11>Settings!$B$9),"Y","N") | AW11: =IF(AJ11<>"Y","n/a",IF(AND(M11>0,AK11>Settings!$B$10),"Y","N")) | AX11: =IF(AO11>=Settings!$B$11,"Y","N") | AY11: =(AT11="Y")+(AU11="Y")+(AV11="Y")+(AW11="Y")+(AX11="Y") | AZ11: =IF(AY11=0,"None",_xlfn.TEXTJOIN(", ",TRUE(),IF(AT11="Y","Breakout",""),IF(AU11="Y","Accumulation",""),IF(AV11="Y","Institutional buying",""),IF(AW11="Y","Long buildup",""),IF(AX11="Y","Momentum leader",""))) | BA11: =IF(BW11="","","Passes "&AY11&" of 5 buy-side scans"&IF(G11="Y","; RED FLAG: filter out using Red flag column","")) | BB11: None | BC11: N | BF11: =IF(R11*100000>=Settings!$B$5,"Y","N") | BG11: =IF(F11>Settings!$B$6,"Y","N") | BH11: -38.06 | BI11: -0.57 | BJ11: -12.41 | BK11: 4.66 | BL11: -13.84 | BM11: -28.8 | BN11: -3.31 | BO11: -6.39 | BP11: -9.44 | BQ11: -15.48 | BR11: Stacked down | BS11: None | BT11: 35.4 | BU11: N | BV11: =IF(OR(BF11<>"Y",BG11<>"Y"),"",(AND(ISNUMBER(BQ11),BQ11>0))+(BR11="Stacked up")+(AND(ISNUMBER(BH11),BH11>=-Settings!$B$17))+(AND(ISNUMBER(BK11),ISNUMBER(BM11),BK11>0,BM11>0))+(AND(ISNUMBER(AQ11),AQ11>=Settings!$B$18))+(AND(ISNUMBER(BT11),BT11>=Settings!$B$19,BT11<=Settings!$B$20))+(AND(ISNUMBER(AS11),AS11>0))+(AND(ISNUMBER(T11),ISNUMBER(M11),T11>=Settings!$B$21,M11>0))+(AND(ISNUMBER(AD11),ISNUMBER(M11),AD11>=Settings!$B$22,M11>0))+(AY11>=1)) | BW11: =IF(OR(AY11=0,BF11<>"Y",BG11<>"Y"),"",1+SUMPRODUCT(($A$6:$A$2604=A11)*($AY$6:$AY$2604>0)*($BF$6:$BF$2604="Y")*($BG$6:$BG$2604="Y")*(($AY$6:$AY$2604>AY11)+($AY$6:$AY$2604=AY11)*($AD$6:$AD$2604>AD11))))
A12: 46296 | B12: BAJFINANCE | C12: INE296A01032 | D12: Financial Services | E12: Nifty 50 | F12: 590407 | G12: N | I12: N | J12: =IF(K12="","N","Y") | K12: =_xlfn.TEXTJOIN("; ",TRUE,IF(P12="52-wk low","52-wk low",""),IF(AND(AD12>=Settings!$B$12,M12<0),"Distribution",""),IF(AND(AJ12="Y",M12<0,AK12<-Settings!$B$13),"Long unwinding",""),IF(AND(AJ12="Y",M12<0,AK12>Settings!$B$13),"Short buildup","")) | L12: 948.3 | M12: -1.16 | N12: 1124 | O12: None | P12: None | Q12: 56.99 | R12: 63.1 | S12: 0.9 | T12: 0.8 | U12: 0.69 | V12: 0.76 | W12: 4 | Y12: None | Z12: 59.38 | AA12: 0.9 | AB12: 0.93 | AC12: 0.83 | AD12: 0.75 | AE12: 0.67 | AF12: 1.05 | AG12: Normal | AH12: 0 | AI12: 0 | AJ12: Y | AK12: 1.56 | AL12: Short buildup | AM12: 21 | AN12: None | AO12: 0 | AP12: 1 | AQ12: 62 | AR12: Y | AS12: 0.6 | AT12: =IF(AND(P12="52-wk high",T12>=Settings!$B$7),"Y","N") | AU12: =IF(AND(AD12>=Settings!$B$8,M12>0),"Y","N") | AV12: =IF(OR(AH12>Settings!$B$9,AI12>Settings!$B$9),"Y","N") | AW12: =IF(AJ12<>"Y","n/a",IF(AND(M12>0,AK12>Settings!$B$10),"Y","N")) | AX12: =IF(AO12>=Settings!$B$11,"Y","N") | AY12: =(AT12="Y")+(AU12="Y")+(AV12="Y")+(AW12="Y")+(AX12="Y") | AZ12: =IF(AY12=0,"None",_xlfn.TEXTJOIN(", ",TRUE(),IF(AT12="Y","Breakout",""),IF(AU12="Y","Accumulation",""),IF(AV12="Y","Institutional buying",""),IF(AW12="Y","Long buildup",""),IF(AX12="Y","Momentum leader",""))) | BA12: =IF(BW12="","","Passes "&AY12&" of 5 buy-side scans"&IF(G12="Y","; RED FLAG: filter out using Red flag column","")) | BB12: None | BC12: N | BF12: =IF(R12*100000>=Settings!$B$5,"Y","N") | BG12: =IF(F12>Settings!$B$6,"Y","N") | BH12: -19.39 | BI12: -3.43 | BJ12: -10.02 | BK12: -6.56 | BL12: 16.03 | BM12: -3.99 | BN12: -6.14 | BO12: -7.88 | BP12: -6.74 | BQ12: -5.42 | BR12: Mixed | BS12: None | BT12: 28.7 | BU12: N | BV12: =IF(OR(BF12<>"Y",BG12<>"Y"),"",(AND(ISNUMBER(BQ12),BQ12>0))+(BR12="Stacked up")+(AND(ISNUMBER(BH12),BH12>=-Settings!$B$17))+(AND(ISNUMBER(BK12),ISNUMBER(BM12),BK12>0,BM12>0))+(AND(ISNUMBER(AQ12),AQ12>=Settings!$B$18))+(AND(ISNUMBER(BT12),BT12>=Settings!$B$19,BT12<=Settings!$B$20))+(AND(ISNUMBER(AS12),AS12>0))+(AND(ISNUMBER(T12),ISNUMBER(M12),T12>=Settings!$B$21,M12>0))+(AND(ISNUMBER(AD12),ISNUMBER(M12),AD12>=Settings!$B$22,M12>0))+(AY12>=1)) | BW12: =IF(OR(AY12=0,BF12<>"Y",BG12<>"Y"),"",1+SUMPRODUCT(($A$6:$A$2604=A12)*($AY$6:$AY$2604>0)*($BF$6:$BF$2604="Y")*($BG$6:$BG$2604="Y")*(($AY$6:$AY$2604>AY12)+($AY$6:$AY$2604=AY12)*($AD$6:$AD$2604>AD12))))
A13: 46296 | B13: LT | C13: INE018A01030 | D13: Construction | E13: Nifty 50 | F13: 508173 | G13: N | I13: N | J13: =IF(K13="","N","Y") | K13: =_xlfn.TEXTJOIN("; ",TRUE,IF(P13="52-wk low","52-wk low",""),IF(AND(AD13>=Settings!$B$12,M13<0),"Distribution",""),IF(AND(AJ13="Y",M13<0,AK13<-Settings!$B$13),"Long unwinding",""),IF(AND(AJ13="Y",M13<0,AK13>Settings!$B$13),"Short buildup","")) | L13: 3693.4 | M13: -1.77 | N13: 1511 | O13: None | P13: None | Q13: 22.21 | R13: 15.83 | S13: 1.45 | T13: 1.47 | U13: 1.23 | V13: 0.87 | W13: 5 | X13: 215 | Y13: By value | Z13: 59.8 | AA13: 0.99 | AB13: 1.04 | AC13: 1.4 | AD13: 1.52 | AE13: 1.31 | AF13: 1.09 | AG13: Normal | AH13: 0 | AI13: 0 | AJ13: Y | AK13: 2.29 | AL13: Short buildup | AM13: 42 | AN13: None | AO13: 0 | AP13: 0.86 | AQ13: 54 | AR13: Y | AS13: 0.78 | AT13: =IF(AND(P13="52-wk high",T13>=Settings!$B$7),"Y","N") | AU13: =IF(AND(AD13>=Settings!$B$8,M13>0),"Y","N") | AV13: =IF(OR(AH13>Settings!$B$9,AI13>Settings!$B$9),"Y","N") | AW13: =IF(AJ13<>"Y","n/a",IF(AND(M13>0,AK13>Settings!$B$10),"Y","N")) | AX13: =IF(AO13>=Settings!$B$11,"Y","N") | AY13: =(AT13="Y")+(AU13="Y")+(AV13="Y")+(AW13="Y")+(AX13="Y") | AZ13: =IF(AY13=0,"None",_xlfn.TEXTJOIN(", ",TRUE(),IF(AT13="Y","Breakout",""),IF(AU13="Y","Accumulation",""),IF(AV13="Y","Institutional buying",""),IF(AW13="Y","Long buildup",""),IF(AX13="Y","Momentum leader",""))) | BA13: =IF(BW13="","","Passes "&AY13&" of 5 buy-side scans"&IF(G13="Y","; RED FLAG: filter out using Red flag column","")) | BB13: None | BC13: N | BF13: =IF(R13*100000>=Settings!$B$5,"Y","N") | BG13: =IF(F13>Settings!$B$6,"Y","N") | BH13: -16.82 | BI13: -4.28 | BJ13: -7.2 | BK13: -9.75 | BL13: 2.38 | BM13: 0.63 | BN13: -4.34 | BO13: -5.89 | BP13: -6.44 | BQ13: -6.12 | BR13: Mixed | BS13: None | BT13: 27.4 | BU13: N | BV13: =IF(OR(BF13<>"Y",BG13<>"Y"),"",(AND(ISNUMBER(BQ13),BQ13>0))+(BR13="Stacked up")+(AND(ISNUMBER(BH13),BH13>=-Settings!$B$17))+(AND(ISNUMBER(BK13),ISNUMBER(BM13),BK13>0,BM13>0))+(AND(ISNUMBER(AQ13),AQ13>=Settings!$B$18))+(AND(ISNUMBER(BT13),BT13>=Settings!$B$19,BT13<=Settings!$B$20))+(AND(ISNUMBER(AS13),AS13>0))+(AND(ISNUMBER(T13),ISNUMBER(M13),T13>=Settings!$B$21,M13>0))+(AND(ISNUMBER(AD13),ISNUMBER(M13),AD13>=Settings!$B$22,M13>0))+(AY13>=1)) | BW13: =IF(OR(AY13=0,BF13<>"Y",BG13<>"Y"),"",1+SUMPRODUCT(($A$6:$A$2604=A13)*($AY$6:$AY$2604>0)*($BF$6:$BF$2604="Y")*($BG$6:$BG$2604="Y")*(($AY$6:$AY$2604>AY13)+($AY$6:$AY$2604=AY13)*($AD$6:$AD$2604>AD13))))
A14: 46296 | B14: SUNPHARMA | C14: INE044A01036 | D14: Healthcare | E14: Nifty 50 | F14: 432120 | G14: N | I14: N | J14: =IF(K14="","N","Y") | K14: =_xlfn.TEXTJOIN("; ",TRUE,IF(P14="52-wk low","52-wk low",""),IF(AND(AD14>=Settings!$B$12,M14<0),"Distribution",""),IF(AND(AJ14="Y",M14<0,AK14<-Settings!$B$13),"Long unwinding",""),IF(AND(AJ14="Y",M14<0,AK14>Settings!$B$13),"Short buildup","")) | L14: 1801 | M14: -0.86 | N14: 966 | O14: None | P14: None | Q14: 23.15 | R14: 15.87 | S14: 1.51 | T14: 1.21 | U14: 1.08 | V14: 0.74 | W14: 5 | X14: 238 | Y14: None | Z14: 63.96 | AA14: 0.98 | AB14: 0.98 | AC14: 1.5 | AD14: 1.19 | AE14: 1.09 | AF14: 1.02 | AG14: Normal | AH14: 0 | AI14: 0 | AJ14: Y | AK14: 2.46 | AL14: Short buildup | AM14: 93 | AN14: None | AO14: 0 | AP14: 1.13 | AQ14: 67 | AR14: Y | AS14: 3.79 | AT14: =IF(AND(P14="52-wk high",T14>=Settings!$B$7),"Y","N") | AU14: =IF(AND(AD14>=Settings!$B$8,M14>0),"Y","N") | AV14: =IF(OR(AH14>Settings!$B$9,AI14>Settings!$B$9),"Y","N") | AW14: =IF(AJ14<>"Y","n/a",IF(AND(M14>0,AK14>Settings!$B$10),"Y","N")) | AX14: =IF(AO14>=Settings!$B$11,"Y","N") | AY14: =(AT14="Y")+(AU14="Y")+(AV14="Y")+(AW14="Y")+(AX14="Y") | AZ14: =IF(AY14=0,"None",_xlfn.TEXTJOIN(", ",TRUE(),IF(AT14="Y","Breakout",""),IF(AU14="Y","Accumulation",""),IF(AV14="Y","Institutional buying",""),IF(AW14="Y","Long buildup",""),IF(AX14="Y","Momentum leader",""))) | BA14: =IF(BW14="","","Passes "&AY14&" of 5 buy-side scans"&IF(G14="Y","; RED FLAG: filter out using Red flag column","")) | BB14: None | BC14: N | BF14: =IF(R14*100000>=Settings!$B$5,"Y","N") | BG14: =IF(F14>Settings!$B$6,"Y","N") | BH14: -12.01 | BI14: -2.64 | BJ14: -6.64 | BK14: -3.49 | BL14: 4.19 | BM14: 10.07 | BN14: -3.07 | BO14: -4.21 | BP14: -3.56 | BQ14: -1.17 | BR14: Mixed | BS14: None | BT14: 34 | BU14: N | BV14: =IF(OR(BF14<>"Y",BG14<>"Y"),"",(AND(ISNUMBER(BQ14),BQ14>0))+(BR14="Stacked up")+(AND(ISNUMBER(BH14),BH14>=-Settings!$B$17))+(AND(ISNUMBER(BK14),ISNUMBER(BM14),BK14>0,BM14>0))+(AND(ISNUMBER(AQ14),AQ14>=Settings!$B$18))+(AND(ISNUMBER(BT14),BT14>=Settings!$B$19,BT14<=Settings!$B$20))+(AND(ISNUMBER(AS14),AS14>0))+(AND(ISNUMBER(T14),ISNUMBER(M14),T14>=Settings!$B$21,M14>0))+(AND(ISNUMBER(AD14),ISNUMBER(M14),AD14>=Settings!$B$22,M14>0))+(AY14>=1)) | BW14: =IF(OR(AY14=0,BF14<>"Y",BG14<>"Y"),"",1+SUMPRODUCT(($A$6:$A$2604=A14)*($AY$6:$AY$2604>0)*($BF$6:$BF$2604="Y")*($BG$6:$BG$2604="Y")*(($AY$6:$AY$2604>AY14)+($AY$6:$AY$2604=AY14)*($AD$6:$AD$2604>AD14))))
A15: 46296 | B15: HINDUNILVR | C15: INE030A01027 | D15: Fast Moving Consumer Goods | E15: Nifty 50 | F15: 431385 | G15: N | I15: N | J15: =IF(K15="","N","Y") | K15: =_xlfn.TEXTJOIN("; ",TRUE,IF(P15="52-wk low","52-wk low",""),IF(AND(AD15>=Settings!$B$12,M15<0),"Distribution",""),IF(AND(AJ15="Y",M15<0,AK15<-Settings!$B$13),"Long unwinding",""),IF(AND(AJ15="Y",M15<0,AK15>Settings!$B$13),"Short buildup","")) | L15: 1836 | M15: -2.29 | N15: 1783 | O15: None | P15: 52-wk low | Q15: 13.32 | R15: 13.48 | S15: 0.98 | T15: 0.89 | U15: 0.79 | V15: 0.8 | W15: 4 | Y15: None | Z15: 52.1 | AA15: 0.86 | AB15: 0.87 | AC15: 0.83 | AD15: 0.78 | AE15: 0.68 | AF15: 1.01 | AG15: Normal | AH15: 0 | AI15: 0 | AJ15: Y | AK15: -0.36 | AL15: Long unwinding | AM15: 99 | AN15: None | AO15: 0 | AP15: 0.49 | AQ15: 4 | AR15: Y | AS15: 2.11 | AT15: =IF(AND(P15="52-wk high",T15>=Settings!$B$7),"Y","N") | AU15: =IF(AND(AD15>=Settings!$B$8,M15>0),"Y","N") | AV15: =IF(OR(AH15>Settings!$B$9,AI15>Settings!$B$9),"Y","N") | AW15: =IF(AJ15<>"Y","n/a",IF(AND(M15>0,AK15>Settings!$B$10),"Y","N")) | AX15: =IF(AO15>=Settings!$B$11,"Y","N") | AY15: =(AT15="Y")+(AU15="Y")+(AV15="Y")+(AW15="Y")+(AX15="Y") | AZ15: =IF(AY15=0,"None",_xlfn.TEXTJOIN(", ",TRUE(),IF(AT15="Y","Breakout",""),IF(AU15="Y","Accumulation",""),IF(AV15="Y","Institutional buying",""),IF(AW15="Y","Long buildup",""),IF(AX15="Y","Momentum leader",""))) | BA15: =IF(BW15="","","Passes "&AY15&" of 5 buy-side scans"&IF(G15="Y","; RED FLAG: filter out using Red flag column","")) | BB15: None | BC15: N | BF15: =IF(R15*100000>=Settings!$B$5,"Y","N") | BG15: =IF(F15>Settings!$B$6,"Y","N") | BH15: -31.16 | BI15: -5.04 | BJ15: -7.96 | BK15: -15.86 | BL15: -11.08 | BM15: -27.61 | BN15: -4.91 | BO15: -8.06 | BP15: -11.32 | BQ15: -15.47 | BR15: Stacked down | BS15: None | BT15: 25.8 | BU15: N | BV15: =IF(OR(BF15<>"Y",BG15<>"Y"),"",(AND(ISNUMBER(BQ15),BQ15>0))+(BR15="Stacked up")+(AND(ISNUMBER(BH15),BH15>=-Settings!$B$17))+(AND(ISNUMBER(BK15),ISNUMBER(BM15),BK15>0,BM15>0))+(AND(ISNUMBER(AQ15),AQ15>=Settings!$B$18))+(AND(ISNUMBER(BT15),BT15>=Settings!$B$19,BT15<=Settings!$B$20))+(AND(ISNUMBER(AS15),AS15>0))+(AND(ISNUMBER(T15),ISNUMBER(M15),T15>=Settings!$B$21,M15>0))+(AND(ISNUMBER(AD15),ISNUMBER(M15),AD15>=Settings!$B$22,M15>0))+(AY15>=1)) | BW15: =IF(OR(AY15=0,BF15<>"Y",BG15<>"Y"),"",1+SUMPRODUCT(($A$6:$A$2604=A15)*($AY$6:$AY$2604>0)*($BF$6:$BF$2604="Y")*($BG$6:$BG$2604="Y")*(($AY$6:$AY$2604>AY15)+($AY$6:$AY$2604=AY15)*($AD$6:$AD$2604>AD15))))
A16: 46296 | B16: INFY | C16: INE009A01021 | D16: Information Technology | E16: Nifty 50 | F16: 420027 | G16: N | I16: N | J16: =IF(K16="","N","Y") | K16: =_xlfn.TEXTJOIN("; ",TRUE,IF(P16="52-wk low","52-wk low",""),IF(AND(AD16>=Settings!$B$12,M16<0),"Distribution",""),IF(AND(AJ16="Y",M16<0,AK16<-Settings!$B$13),"Long unwinding",""),IF(AND(AJ16="Y",M16<0,AK16>Settings!$B$13),"Short buildup","")) | L16: 1035 | M16: 4.11 | N16: 86 | O16: None | P16: None | Q16: 151.66 | R16: 95.42 | S16: 1.65 | T16: 1.42 | U16: 1.19 | V16: 0.75 | W16: 6 | X16: 210 | Y16: By value | Z16: 51.96 | AA16: 0.93 | AB16: 0.93 | AC16: 1.49 | AD16: 1.32 | AE16: 1.12 | AF16: 1.03 | AG16: Normal | AH16: 0 | AI16: 0 | AJ16: Y | AK16: 3.81 | AL16: Long buildup | AM16: 2 | AN16: None | AO16: 0 | AP16: 0.51 | AQ16: 6 | AR16: Y | AS16: -0.75 | AT16: =IF(AND(P16="52-wk high",T16>=Settings!$B$7),"Y","N") | AU16: =IF(AND(AD16>=Settings!$B$8,M16>0),"Y","N") | AV16: =IF(OR(AH16>Settings!$B$9,AI16>Settings!$B$9),"Y","N") | AW16: =IF(AJ16<>"Y","n/a",IF(AND(M16>0,AK16>Settings!$B$10),"Y","N")) | AX16: =IF(AO16>=Settings!$B$11,"Y","N") | AY16: =(AT16="Y")+(AU16="Y")+(AV16="Y")+(AW16="Y")+(AX16="Y") | AZ16: =IF(AY16=0,"None",_xlfn.TEXTJOIN(", ",TRUE(),IF(AT16="Y","Breakout",""),IF(AU16="Y","Accumulation",""),IF(AV16="Y","Institutional buying",""),IF(AW16="Y","Long buildup",""),IF(AX16="Y","Momentum leader",""))) | BA16: =IF(BW16="","","Passes "&AY16&" of 5 buy-side scans"&IF(G16="Y","; RED FLAG: filter out using Red flag column","")) | BB16: None | BC16: N | BF16: =IF(R16*100000>=Settings!$B$5,"Y","N") | BG16: =IF(F16>Settings!$B$6,"Y","N") | BH16: -40.1 | BI16: 2.02 | BJ16: -10.47 | BK16: 5.04 | BL16: -18.87 | BM16: -28.41 | BN16: -0.99 | BO16: -4.35 | BP16: -8.34 | BQ16: -15.12 | BR16: Stacked down | BS16: None | BT16: 48.3 | BU16: N | BV16: =IF(OR(BF16<>"Y",BG16<>"Y"),"",(AND(ISNUMBER(BQ16),BQ16>0))+(BR16="Stacked up")+(AND(ISNUMBER(BH16),BH16>=-Settings!$B$17))+(AND(ISNUMBER(BK16),ISNUMBER(BM16),BK16>0,BM16>0))+(AND(ISNUMBER(AQ16),AQ16>=Settings!$B$18))+(AND(ISNUMBER(BT16),BT16>=Settings!$B$19,BT16<=Settings!$B$20))+(AND(ISNUMBER(AS16),AS16>0))+(AND(ISNUMBER(T16),ISNUMBER(M16),T16>=Settings!$B$21,M16>0))+(AND(ISNUMBER(AD16),ISNUMBER(M16),AD16>=Settings!$B$22,M16>0))+(AY16>=1)) | BW16: =IF(OR(AY16=0,BF16<>"Y",BG16<>"Y"),"",1+SUMPRODUCT(($A$6:$A$2604=A16)*($AY$6:$AY$2604>0)*($BF$6:$BF$2604="Y")*($BG$6:$BG$2604="Y")*(($AY$6:$AY$2604>AY16)+($AY$6:$AY$2604=AY16)*($AD$6:$AD$2604>AD16))))
A17: 46296 | B17: KOTAKBANK | C17: INE237A01036 | D17: Financial Services | E17: Nifty 50 | F17: 416160 | G17: N | I17: N | J17: =IF(K17="","N","Y") | K17: =_xlfn.TEXTJOIN("; ",TRUE,IF(P17="52-wk low","52-wk low",""),IF(AND(AD17>=Settings!$B$12,M17<0),"Distribution",""),IF(AND(AJ17="Y",M17<0,AK17<-Settings!$B$13),"Long unwinding",""),IF(AND(AJ17="Y",M17<0,AK17>Settings!$B$13),"Short buildup","")) | L17: 418.35 | M17: 0.32 | N17: 491 | O17: None | P17: None | Q17: 766.37 | R17: 164.86 | S17: 5.83 | T17: 6.16 | U17: 5.24 | V17: 1.09 | W17: 5 | X17: 18 | Y17: Both | Z17: 58.17 | AA17: 0.85 | AB17: 0.86 | AC17: 4.82 | AD17: 5.21 | AE17: 4.62 | AF17: 1.03 | AG17: Normal | AH17: 0 | AI17: 0 | AJ17: Y | AK17: -1.97 | AL17: Short covering | AM17: 1 | AN17: None | AO17: 0 | AR17: Y | AS17: 0.6 | AT17: =IF(AND(P17="52-wk high",T17>=Settings!$B$7),"Y","N") | AU17: =IF(AND(AD17>=Settings!$B$8,M17>0),"Y","N") | AV17: =IF(OR(AH17>Settings!$B$9,AI17>Settings!$B$9),"Y","N") | AW17: =IF(AJ17<>"Y","n/a",IF(AND(M17>0,AK17>Settings!$B$10),"Y","N")) | AX17: =IF(AO17>=Settings!$B$11,"Y","N") | AY17: =(AT17="Y")+(AU17="Y")+(AV17="Y")+(AW17="Y")+(AX17="Y") | AZ17: =IF(AY17=0,"None",_xlfn.TEXTJOIN(", ",TRUE(),IF(AT17="Y","Breakout",""),IF(AU17="Y","Accumulation",""),IF(AV17="Y","Institutional buying",""),IF(AW17="Y","Long buildup",""),IF(AX17="Y","Momentum leader",""))) | BA17: =IF(BW17="","","Passes "&AY17&" of 5 buy-side scans"&IF(G17="Y","; RED FLAG: filter out using Red flag column","")) | BB17: Upper | BC17: N | BF17: =IF(R17*100000>=Settings!$B$5,"Y","N") | BG17: =IF(F17>Settings!$B$6,"Y","N") | BH17: -7.69 | BI17: 3.3 | BJ17: -1.56 | BK17: 4.47 | BL17: 17.5 | BN17: 1.64 | BO17: 2.96 | BP17: 4.3 | BS17: None | BT17: 60.2 | BV17: =IF(OR(BF17<>"Y",BG17<>"Y"),"",(AND(ISNUMBER(BQ17),BQ17>0))+(BR17="Stacked up")+(AND(ISNUMBER(BH17),BH17>=-Settings!$B$17))+(AND(ISNUMBER(BK17),ISNUMBER(BM17),BK17>0,BM17>0))+(AND(ISNUMBER(AQ17),AQ17>=Settings!$B$18))+(AND(ISNUMBER(BT17),BT17>=Settings!$B$19,BT17<=Settings!$B$20))+(AND(ISNUMBER(AS17),AS17>0))+(AND(ISNUMBER(T17),ISNUMBER(M17),T17>=Settings!$B$21,M17>0))+(AND(ISNUMBER(AD17),ISNUMBER(M17),AD17>=Settings!$B$22,M17>0))+(AY17>=1)) | BW17: =IF(OR(AY17=0,BF17<>"Y",BG17<>"Y"),"",1+SUMPRODUCT(($A$6:$A$2604=A17)*($AY$6:$AY$2604>0)*($BF$6:$BF$2604="Y")*($BG$6:$BG$2604="Y")*(($AY$6:$AY$2604>AY17)+($AY$6:$AY$2604=AY17)*($AD$6:$AD$2604>AD17))))
A18: 46296 | B18: TITAN | C18: INE280A01028 | D18: Consumer Durables | E18: Nifty 50 | F18: 400898 | G18: N | I18: N | J18: =IF(K18="","N","Y") | K18: =_xlfn.TEXTJOIN("; ",TRUE,IF(P18="52-wk low","52-wk low",""),IF(AND(AD18>=Settings!$B$12,M18<0),"Distribution",""),IF(AND(AJ18="Y",M18<0,AK18<-Settings!$B$13),"Long unwinding",""),IF(AND(AJ18="Y",M18<0,AK18>Settings!$B$13),"Short buildup","")) | L18: 4515.7 | M18: -1.55 | N18: 1366 | O18: None | P18: None | Q18: 6.94 | R18: 6.23 | S18: 1.1 | T18: 0.93 | U18: 0.77 | V18: 0.73 | W18: 3 | Y18: None | Z18: 57.67 | AA18: 0.99 | AB18: 1 | AC18: 1.08 | AD18: 0.96 | AE18: 0.83 | AF18: 1.09 | AG18: Normal | AH18: 0 | AI18: 0 | AJ18: Y | AK18: 2.29 | AL18: Short buildup | AM18: 48 | AN18: None | AO18: 0 | AP18: 1.65 | AQ18: 83 | AR18: Y | AS18: 0.75 | AT18: =IF(AND(P18="52-wk high",T18>=Settings!$B$7),"Y","N") | AU18: =IF(AND(AD18>=Settings!$B$8,M18>0),"Y","N") | AV18: =IF(OR(AH18>Settings!$B$9,AI18>Settings!$B$9),"Y","N") | AW18: =IF(AJ18<>"Y","n/a",IF(AND(M18>0,AK18>Settings!$B$10),"Y","N")) | AX18: =IF(AO18>=Settings!$B$11,"Y","N") | AY18: =(AT18="Y")+(AU18="Y")+(AV18="Y")+(AW18="Y")+(AX18="Y") | AZ18: =IF(AY18=0,"None",_xlfn.TEXTJOIN(", ",TRUE(),IF(AT18="Y","Breakout",""),IF(AU18="Y","Accumulation",""),IF(AV18="Y","Institutional buying",""),IF(AW18="Y","Long buildup",""),IF(AX18="Y","Momentum leader",""))) | BA18: =IF(BW18="","","Passes "&AY18&" of 5 buy-side scans"&IF(G18="Y","; RED FLAG: filter out using Red flag column","")) | BB18: None | BC18: Y | BD18: PE > 50 | BF18: =IF(R18*100000>=Settings!$B$5,"Y","N") | BG18: =IF(F18>Settings!$B$6,"Y","N") | BH18: -12.94 | BI18: -6.56 | BJ18: -10.58 | BK18: 2.66 | BL18: 11.07 | BM18: 32.49 | BN18: -6.6 | BO18: -6.79 | BP18: -3.9 | BQ18: 1.71 | BR18: Mixed | BS18: Bearish cross | BT18: 21 | BU18: N | BV18: =IF(OR(BF18<>"Y",BG18<>"Y"),"",(AND(ISNUMBER(BQ18),BQ18>0))+(BR18="Stacked up")+(AND(ISNUMBER(BH18),BH18>=-Settings!$B$17))+(AND(ISNUMBER(BK18),ISNUMBER(BM18),BK18>0,BM18>0))+(AND(ISNUMBER(AQ18),AQ18>=Settings!$B$18))+(AND(ISNUMBER(BT18),BT18>=Settings!$B$19,BT18<=Settings!$B$20))+(AND(ISNUMBER(AS18),AS18>0))+(AND(ISNUMBER(T18),ISNUMBER(M18),T18>=Settings!$B$21,M18>0))+(AND(ISNUMBER(AD18),ISNUMBER(M18),AD18>=Settings!$B$22,M18>0))+(AY18>=1)) | BW18: =IF(OR(AY18=0,BF18<>"Y",BG18<>"Y"),"",1+SUMPRODUCT(($A$6:$A$2604=A18)*($AY$6:$AY$2604>0)*($BF$6:$BF$2604="Y")*($BG$6:$BG$2604="Y")*(($AY$6:$AY$2604>AY18)+($AY$6:$AY$2604=AY18)*($AD$6:$AD$2604>AD18))))
A19: 46296 | B19: ADANIPORTS | C19: INE742F01042 | D19: Services | E19: Nifty 50 | F19: 400382 | G19: N | I19: N | J19: =IF(K19="","N","Y") | K19: =_xlfn.TEXTJOIN("; ",TRUE,IF(P19="52-wk low","52-wk low",""),IF(AND(AD19>=Settings!$B$12,M19<0),"Distribution",""),IF(AND(AJ19="Y",M19<0,AK19<-Settings!$B$13),"Long unwinding",""),IF(AND(AJ19="Y",M19<0,AK19>Settings!$B$13),"Short buildup","")) | L19: 1737.8 | M19: -3.36 | N19: 2185 | O19: None | P19: None | Q19: 21.58 | R19: 21.17 | S19: 1.02 | T19: 0.93 | U19: 0.96 | V19: 0.95 | W19: 6 | Y19: None | Z19: 52.62 | AA19: 0.9 | AB19: 0.92 | AC19: 0.89 | AD19: 0.83 | AE19: 0.95 | AF19: 1.13 | AG19: Normal | AH19: 0 | AI19: 0 | AJ19: Y | AK19: -2.41 | AL19: Long unwinding | AM19: 51 | AN19: None | AO19: 0 | AP19: 1.58 | AQ19: 81 | AR19: Y | AS19: 5.23 | AT19: =IF(AND(P19="52-wk high",T19>=Settings!$B$7),"Y","N") | AU19: =IF(AND(AD19>=Settings!$B$8,M19>0),"Y","N") | AV19: =IF(OR(AH19>Settings!$B$9,AI19>Settings!$B$9),"Y","N") | AW19: =IF(AJ19<>"Y","n/a",IF(AND(M19>0,AK19>Settings!$B$10),"Y","N")) | AX19: =IF(AO19>=Settings!$B$11,"Y","N") | AY19: =(AT19="Y")+(AU19="Y")+(AV19="Y")+(AW19="Y")+(AX19="Y") | AZ19: =IF(AY19=0,"None",_xlfn.TEXTJOIN(", ",TRUE(),IF(AT19="Y","Breakout",""),IF(AU19="Y","Accumulation",""),IF(AV19="Y","Institutional buying",""),IF(AW19="Y","Long buildup",""),IF(AX19="Y","Momentum leader",""))) | BA19: =IF(BW19="","","Passes "&AY19&" of 5 buy-side scans"&IF(G19="Y","; RED FLAG: filter out using Red flag column","")) | BB19: None | BC19: N | BF19: =IF(R19*100000>=Settings!$B$5,"Y","N") | BG19: =IF(F19>Settings!$B$6,"Y","N") | BH19: -8.11 | BI19: -2.66 | BJ19: 5.48 | BK19: -5.97 | BL19: 25.44 | BM19: 22.15 | BN19: -1.25 | BO19: -0.33 | BP19: 1.08 | BQ19: 4.92 | BR19: Mixed | BS19: None | BT19: 45.2 | BU19: N | BV19: =IF(OR(BF19<>"Y",BG19<>"Y"),"",(AND(ISNUMBER(BQ19),BQ19>0))+(BR19="Stacked up")+(AND(ISNUMBER(BH19),BH19>=-Settings!$B$17))+(AND(ISNUMBER(BK19),ISNUMBER(BM19),BK19>0,BM19>0))+(AND(ISNUMBER(AQ19),AQ19>=Settings!$B$18))+(AND(ISNUMBER(BT19),BT19>=Settings!$B$19,BT19<=Settings!$B$20))+(AND(ISNUMBER(AS19),AS19>0))+(AND(ISNUMBER(T19),ISNUMBER(M19),T19>=Settings!$B$21,M19>0))+(AND(ISNUMBER(AD19),ISNUMBER(M19),AD19>=Settings!$B$22,M19>0))+(AY19>=1)) | BW19: =IF(OR(AY19=0,BF19<>"Y",BG19<>"Y"),"",1+SUMPRODUCT(($A$6:$A$2604=A19)*($AY$6:$AY$2604>0)*($BF$6:$BF$2604="Y")*($BG$6:$BG$2604="Y")*(($AY$6:$AY$2604>AY19)+($AY$6:$AY$2604=AY19)*($AD$6:$AD$2604>AD19))))
A20: 46296 | B20: ADANIENT | C20: INE423A01024 | D20: Metals & Mining | E20: Nifty 50 | F20: 381234 | G20: N | I20: N | J20: =IF(K20="","N","Y") | K20: =_xlfn.TEXTJOIN("; ",TRUE,IF(P20="52-wk low","52-wk low",""),IF(AND(AD20>=Settings!$B$12,M20<0),"Distribution",""),IF(AND(AJ20="Y",M20<0,AK20<-Settings!$B$13),"Long unwinding",""),IF(AND(AJ20="Y",M20<0,AK20>Settings!$B$13),"Short buildup","")) | L20: 2816.8 | M20: -2.98 | N20: 2082 | O20: None | P20: None | Q20: 21 | R20: 15.31 | S20: 1.39 | T20: 1.34 | U20: 1.07 | V20: 0.77 | W20: 3 | X20: 238 | Y20: None | Z20: 42.05 | AA20: 1.03 | AB20: 1.03 | AC20: 1.33 | AD20: 1.19 | AE20: 1.18 | AF20: 1.16 | AG20: Normal | AH20: 0 | AI20: 0 | AJ20: Y | AK20: 0.71 | AL20: Short buildup | AM20: 33 | AN20: None | AO20: 0 | AP20: 1.66 | AQ20: 83 | AR20: Y | AS20: -1.09 | AT20: =IF(AND(P20="52-wk high",T20>=Settings!$B$7),"Y","N") | AU20: =IF(AND(AD20>=Settings!$B$8,M20>0),"Y","N") | AV20: =IF(OR(AH20>Settings!$B$9,AI20>Settings!$B$9),"Y","N") | AW20: =IF(AJ20<>"Y","n/a",IF(AND(M20>0,AK20>Settings!$B$10),"Y","N")) | AX20: =IF(AO20>=Settings!$B$11,"Y","N") | AY20: =(AT20="Y")+(AU20="Y")+(AV20="Y")+(AW20="Y")+(AX20="Y") | AZ20: =IF(AY20=0,"None",_xlfn.TEXTJOIN(", ",TRUE(),IF(AT20="Y","Breakout",""),IF(AU20="Y","Accumulation",""),IF(AV20="Y","Institutional buying",""),IF(AW20="Y","Long buildup",""),IF(AX20="Y","Momentum leader",""))) | BA20: =IF(BW20="","","Passes "&AY20&" of 5 buy-side scans"&IF(G20="Y","; RED FLAG: filter out using Red flag column","")) | BB20: None | BC20: Y | BD20: PE > 50 | BF20: =IF(R20*100000>=Settings!$B$5,"Y","N") | BG20: =IF(F20>Settings!$B$6,"Y","N") | BH20: -13.2 | BI20: -2.87 | BJ20: -1.64 | BK20: -10.4 | BL20: 52.88 | BM20: 8.64 | BN20: -4.32 | BO20: -5.05 | BP20: -2.39 | BQ20: 2.94 | BR20: Mixed | BS20: None | BT20: 38 | BU20: N | BV20: =IF(OR(BF20<>"Y",BG20<>"Y"),"",(AND(ISNUMBER(BQ20),BQ20>0))+(BR20="Stacked up")+(AND(ISNUMBER(BH20),BH20>=-Settings!$B$17))+(AND(ISNUMBER(BK20),ISNUMBER(BM20),BK20>0,BM20>0))+(AND(ISNUMBER(AQ20),AQ20>=Settings!$B$18))+(AND(ISNUMBER(BT20),BT20>=Settings!$B$19,BT20<=Settings!$B$20))+(AND(ISNUMBER(AS20),AS20>0))+(AND(ISNUMBER(T20),ISNUMBER(M20),T20>=Settings!$B$21,M20>0))+(AND(ISNUMBER(AD20),ISNUMBER(M20),AD20>=Settings!$B$22,M20>0))+(AY20>=1)) | BW20: =IF(OR(AY20=0,BF20<>"Y",BG20<>"Y"),"",1+SUMPRODUCT(($A$6:$A$2604=A20)*($AY$6:$AY$2604>0)*($BF$6:$BF$2604="Y")*($BG$6:$BG$2604="Y")*(($AY$6:$AY$2604>AY20)+($AY$6:$AY$2604=AY20)*($AD$6:$AD$2604>AD20))))
A21: 46296 | B21: AXISBANK | C21: INE238A01034 | D21: Financial Services | E21: Nifty 50 | F21: 378953 | G21: N | I21: N | J21: =IF(K21="","N","Y") | K21: =_xlfn.TEXTJOIN("; ",TRUE,IF(P21="52-wk low","52-wk low",""),IF(AND(AD21>=Settings!$B$12,M21<0),"Distribution",""),IF(AND(AJ21="Y",M21<0,AK21<-Settings!$B$13),"Long unwinding",""),IF(AND(AJ21="Y",M21<0,AK21>Settings!$B$13),"Short buildup","")) | L21: 1217.1 | M21: -0.73 | N21: 897 | O21: None | P21: None | Q21: 70.05 | R21: 50.51 | S21: 1.39 | T21: 1.3 | U21: 1.11 | V21: 0.8 | W21: 5 | X21: 238 | Y21: By value | Z21: 60.93 | AA21: 0.99 | AB21: 0.96 | AC21: 1.38 | AD21: 1.23 | AE21: 1.07 | AF21: 0.98 | AG21: Normal | AH21: 0 | AI21: 0 | AJ21: Y | AK21: -0.27 | AL21: Long unwinding | AM21: 9 | AN21: None | AO21: 0 | AP21: 0.92 | AQ21: 58 | AR21: Y | AS21: 0.6 | AT21: =IF(AND(P21="52-wk high",T21>=Settings!$B$7),"Y","N") | AU21: =IF(AND(AD21>=Settings!$B$8,M21>0),"Y","N") | AV21: =IF(OR(AH21>Settings!$B$9,AI21>Settings!$B$9),"Y","N") | AW21: =IF(AJ21<>"Y","n/a",IF(AND(M21>0,AK21>Settings!$B$10),"Y","N")) | AX21: =IF(AO21>=Settings!$B$11,"Y","N") | AY21: =(AT21="Y")+(AU21="Y")+(AV21="Y")+(AW21="Y")+(AX21="Y") | AZ21: =IF(AY21=0,"None",_xlfn.TEXTJOIN(", ",TRUE(),IF(AT21="Y","Breakout",""),IF(AU21="Y","Accumulation",""),IF(AV21="Y","Institutional buying",""),IF(AW21="Y","Long buildup",""),IF(AX21="Y","Momentum leader",""))) | BA21: =IF(BW21="","","Passes "&AY21&" of 5 buy-side scans"&IF(G21="Y","; RED FLAG: filter out using Red flag column","")) | BB21: None | BC21: N | BF21: =IF(R21*100000>=Settings!$B$5,"Y","N") | BG21: =IF(F21>Settings!$B$6,"Y","N") | BH21: -14.19 | BI21: 2.58 | BJ21: -3.25 | BK21: -11.08 | BL21: 2.01 | BM21: 4.97 | BN21: -1.25 | BO21: -2.49 | BP21: -3.61 | BQ21: -3.63 | BR21: Stacked down | BS21: None | BT21: 44.2 | BU21: N | BV21: =IF(OR(BF21<>"Y",BG21<>"Y"),"",(AND(ISNUMBER(BQ21),BQ21>0))+(BR21="Stacked up")+(AND(ISNUMBER(BH21),BH21>=-Settings!$B$17))+(AND(ISNUMBER(BK21),ISNUMBER(BM21),BK21>0,BM21>0))+(AND(ISNUMBER(AQ21),AQ21>=Settings!$B$18))+(AND(ISNUMBER(BT21),BT21>=Settings!$B$19,BT21<=Settings!$B$20))+(AND(ISNUMBER(AS21),AS21>0))+(AND(ISNUMBER(T21),ISNUMBER(M21),T21>=Settings!$B$21,M21>0))+(AND(ISNUMBER(AD21),ISNUMBER(M21),AD21>=Settings!$B$22,M21>0))+(AY21>=1)) | BW21: =IF(OR(AY21=0,BF21<>"Y",BG21<>"Y"),"",1+SUMPRODUCT(($A$6:$A$2604=A21)*($AY$6:$AY$2604>0)*($BF$6:$BF$2604="Y")*($BG$6:$BG$2604="Y")*(($AY$6:$AY$2604>AY21)+($AY$6:$AY$2604=AY21)*($AD$6:$AD$2604>AD21))))
A22: 46296 | B22: MARUTI | C22: INE585B01010 | D22: Automobile and Auto Components | E22: Nifty 50 | F22: 357979 | G22: N | I22: N | J22: =IF(K22="","N","Y") | K22: =_xlfn.TEXTJOIN("; ",TRUE,IF(P22="52-wk low","52-wk low",""),IF(AND(AD22>=Settings!$B$12,M22<0),"Distribution",""),IF(AND(AJ22="Y",M22<0,AK22<-Settings!$B$13),"Long unwinding",""),IF(AND(AJ22="Y",M22<0,AK22>Settings!$B$13),"Short buildup","")) | L22: 11386 | M22: -4.86 | N22: 2458 | O22: None | P22: 52-wk low | Q22: 8.86 | R22: 3.99 | S22: 2.3 | T22: 2.36 | U22: 2.1 | V22: 0.94 | W22: 6 | X22: 86 | Y22: By value | Z22: 45.98 | AA22: 0.84 | AB22: 0.85 | AC22: 1.91 | AD22: 1.99 | AE22: 1.8 | AF22: 1.01 | AG22: Normal | AH22: 0 | AI22: 0 | AJ22: Y | AK22: 2 | AL22: Short buildup | AM22: 17 | AN22: None | AO22: 0 | AP22: 0.51 | AQ22: 6 | AR22: Y | AS22: 0.56 | AT22: =IF(AND(P22="52-wk high",T22>=Settings!$B$7),"Y","N") | AU22: =IF(AND(AD22>=Settings!$B$8,M22>0),"Y","N") | AV22: =IF(OR(AH22>Settings!$B$9,AI22>Settings!$B$9),"Y","N") | AW22: =IF(AJ22<>"Y","n/a",IF(AND(M22>0,AK22>Settings!$B$10),"Y","N")) | AX22: =IF(AO22>=Settings!$B$11,"Y","N") | AY22: =(AT22="Y")+(AU22="Y")+(AV22="Y")+(AW22="Y")+(AX22="Y") | AZ22: =IF(AY22=0,"None",_xlfn.TEXTJOIN(", ",TRUE(),IF(AT22="Y","Breakout",""),IF(AU22="Y","Accumulation",""),IF(AV22="Y","Institutional buying",""),IF(AW22="Y","Long buildup",""),IF(AX22="Y","Momentum leader",""))) | BA22: =IF(BW22="","","Passes "&AY22&" of 5 buy-side scans"&IF(G22="Y","; RED FLAG: filter out using Red flag column","")) | BB22: Upper | BC22: N | BF22: =IF(R22*100000>=Settings!$B$5,"Y","N") | BG22: =IF(F22>Settings!$B$6,"Y","N") | BH22: -34.45 | BI22: -5.04 | BJ22: -12.08 | BK22: -20.9 | BL22: -8.98 | BM22: -28.68 | BN22: -7.31 | BO22: -11.38 | BP22: -14.13 | BQ22: -17.89 | BR22: Stacked down | BS22: None | BT22: 18.8 | BU22: N | BV22: =IF(OR(BF22<>"Y",BG22<>"Y"),"",(AND(ISNUMBER(BQ22),BQ22>0))+(BR22="Stacked up")+(AND(ISNUMBER(BH22),BH22>=-Settings!$B$17))+(AND(ISNUMBER(BK22),ISNUMBER(BM22),BK22>0,BM22>0))+(AND(ISNUMBER(AQ22),AQ22>=Settings!$B$18))+(AND(ISNUMBER(BT22),BT22>=Settings!$B$19,BT22<=Settings!$B$20))+(AND(ISNUMBER(AS22),AS22>0))+(AND(ISNUMBER(T22),ISNUMBER(M22),T22>=Settings!$B$21,M22>0))+(AND(ISNUMBER(AD22),ISNUMBER(M22),AD22>=Settings!$B$22,M22>0))+(AY22>=1)) | BW22: =IF(OR(AY22=0,BF22<>"Y",BG22<>"Y"),"",1+SUMPRODUCT(($A$6:$A$2604=A22)*($AY$6:$AY$2604>0)*($BF$6:$BF$2604="Y")*($BG$6:$BG$2604="Y")*(($AY$6:$AY$2604>AY22)+($AY$6:$AY$2604=AY22)*($AD$6:$AD$2604>AD22))))
A23: 46296 | B23: M&M | C23: INE101A01026 | D23: Automobile and Auto Components | E23: Nifty 50 | F23: 355649 | G23: N | I23: N | J23: =IF(K23="","N","Y") | K23: =_xlfn.TEXTJOIN("; ",TRUE,IF(P23="52-wk low","52-wk low",""),IF(AND(AD23>=Settings!$B$12,M23<0),"Distribution",""),IF(AND(AJ23="Y",M23<0,AK23<-Settings!$B$13),"Long unwinding",""),IF(AND(AJ23="Y",M23<0,AK23>Settings!$B$13),"Short buildup","")) | L23: 2860 | M23: -3.05 | N23: 2107 | O23: None | P23: 52-wk low | Q23: 54.53 | R23: 21.61 | S23: 2.68 | T23: 2.53 | U23: 2.16 | V23: 0.85 | W23: 3 | X23: 62 | Y23: By value | Z23: 58.85 | AA23: 0.94 | AB23: 0.97 | AC23: 2.52 | AD23: 2.46 | AE23: 2.17 | AF23: 1.06 | AG23: Normal | AH23: 0 | AI23: 0 | AJ23: Y | AK23: -4.8 | AL23: Long unwinding | AM23: 8 | AN23: None | AO23: 0 | AP23: 0.62 | AQ23: 23 | AR23: Y | AS23: 0.56 | AT23: =IF(AND(P23="52-wk high",T23>=Settings!$B$7),"Y","N") | AU23: =IF(AND(AD23>=Settings!$B$8,M23>0),"Y","N") | AV23: =IF(OR(AH23>Settings!$B$9,AI23>Settings!$B$9),"Y","N") | AW23: =IF(AJ23<>"Y","n/a",IF(AND(M23>0,AK23>Settings!$B$10),"Y","N")) | AX23: =IF(AO23>=Settings!$B$11,"Y","N") | AY23: =(AT23="Y")+(AU23="Y")+(AV23="Y")+(AW23="Y")+(AX23="Y") | AZ23: =IF(AY23=0,"None",_xlfn.TEXTJOIN(", ",TRUE(),IF(AT23="Y","Breakout",""),IF(AU23="Y","Accumulation",""),IF(AV23="Y","Institutional buying",""),IF(AW23="Y","Long buildup",""),IF(AX23="Y","Momentum leader",""))) | BA23: =IF(BW23="","","Passes "&AY23&" of 5 buy-side scans"&IF(G23="Y","; RED FLAG: filter out using Red flag column","")) | BB23: None | BC23: N | BF23: =IF(R23*100000>=Settings!$B$5,"Y","N") | BG23: =IF(F23>Settings!$B$6,"Y","N") | BH23: -25.52 | BI23: -4.11 | BJ23: -12.24 | BK23: -8.63 | BL23: -5.66 | BM23: -17.42 | BN23: -6.51 | BO23: -9.34 | BP23: -10.52 | BQ23: -12.53 | BR23: Stacked down | BS23: None | BT23: 18.4 | BU23: N | BV23: =IF(OR(BF23<>"Y",BG23<>"Y"),"",(AND(ISNUMBER(BQ23),BQ23>0))+(BR23="Stacked up")+(AND(ISNUMBER(BH23),BH23>=-Settings!$B$17))+(AND(ISNUMBER(BK23),ISNUMBER(BM23),BK23>0,BM23>0))+(AND(ISNUMBER(AQ23),AQ23>=Settings!$B$18))+(AND(ISNUMBER(BT23),BT23>=Settings!$B$19,BT23<=Settings!$B$20))+(AND(ISNUMBER(AS23),AS23>0))+(AND(ISNUMBER(T23),ISNUMBER(M23),T23>=Settings!$B$21,M23>0))+(AND(ISNUMBER(AD23),ISNUMBER(M23),AD23>=Settings!$B$22,M23>0))+(AY23>=1)) | BW23: =IF(OR(AY23=0,BF23<>"Y",BG23<>"Y"),"",1+SUMPRODUCT(($A$6:$A$2604=A23)*($AY$6:$AY$2604>0)*($BF$6:$BF$2604="Y")*($BG$6:$BG$2604="Y")*(($AY$6:$AY$2604>AY23)+($AY$6:$AY$2604=AY23)*($AD$6:$AD$2604>AD23))))
A24: 46296 | B24: HCLTECH | C24: INE860A01027 | D24: Information Technology | E24: Nifty 50 | F24: 337336 | G24: N | I24: N | J24: =IF(K24="","N","Y") | K24: =_xlfn.TEXTJOIN("; ",TRUE,IF(P24="52-wk low","52-wk low",""),IF(AND(AD24>=Settings!$B$12,M24<0),"Distribution",""),IF(AND(AJ24="Y",M24<0,AK24<-Settings!$B$13),"Long unwinding",""),IF(AND(AJ24="Y",M24<0,AK24>Settings!$B$13),"Short buildup","")) | L24: 1243.1 | M24: 1.07 | N24: 319 | O24: None | P24: None | Q24: 34.3 | R24: 26.2 | S24: 1.33 | T24: 1.38 | U24: 1.03 | V24: 0.78 | W24: 4 | X24: 248 | Y24: None | Z24: 52.43 | AA24: 1.05 | AB24: 1.02 | AC24: 1.36 | AD24: 1.4 | AE24: 1.12 | AF24: 1.06 | AG24: Normal | AH24: 0 | AI24: 0 | AJ24: Y | AK24: 0.89 | AL24: Long buildup | AM24: 43 | AN24: None | AO24: 0 | AP24: 0.65 | AQ24: 29 | AR24: Y | AS24: -0.75 | AT24: =IF(AND(P24="52-wk high",T24>=Settings!$B$7),"Y","N") | AU24: =IF(AND(AD24>=Settings!$B$8,M24>0),"Y","N") | AV24: =IF(OR(AH24>Settings!$B$9,AI24>Settings!$B$9),"Y","N") | AW24: =IF(AJ24<>"Y","n/a",IF(AND(M24>0,AK24>Settings!$B$10),"Y","N")) | AX24: =IF(AO24>=Settings!$B$11,"Y","N") | AY24: =(AT24="Y")+(AU24="Y")+(AV24="Y")+(AW24="Y")+(AX24="Y") | AZ24: =IF(AY24=0,"None",_xlfn.TEXTJOIN(", ",TRUE(),IF(AT24="Y","Breakout",""),IF(AU24="Y","Accumulation",""),IF(AV24="Y","Institutional buying",""),IF(AW24="Y","Long buildup",""),IF(AX24="Y","Momentum leader",""))) | BA24: =IF(BW24="","","Passes "&AY24&" of 5 buy-side scans"&IF(G24="Y","; RED FLAG: filter out using Red flag column","")) | BB24: None | BC24: N | BF24: =IF(R24*100000>=Settings!$B$5,"Y","N") | BG24: =IF(F24>Settings!$B$6,"Y","N") | BH24: -30.17 | BI24: -0.04 | BJ24: -8.01 | BK24: 20.2 | BL24: -8.22 | BM24: -10.54 | BN24: -1.2 | BO24: -1.87 | BP24: -2.56 | BQ24: -5.93 | BR24: Stacked down | BS24: None | BT24: 45.2 | BU24: N | BV24: =IF(OR(BF24<>"Y",BG24<>"Y"),"",(AND(ISNUMBER(BQ24),BQ24>0))+(BR24="Stacked up")+(AND(ISNUMBER(BH24),BH24>=-Settings!$B$17))+(AND(ISNUMBER(BK24),ISNUMBER(BM24),BK24>0,BM24>0))+(AND(ISNUMBER(AQ24),AQ24>=Settings!$B$18))+(AND(ISNUMBER(BT24),BT24>=Settings!$B$19,BT24<=Settings!$B$20))+(AND(ISNUMBER(AS24),AS24>0))+(AND(ISNUMBER(T24),ISNUMBER(M24),T24>=Settings!$B$21,M24>0))+(AND(ISNUMBER(AD24),ISNUMBER(M24),AD24>=Settings!$B$22,M24>0))+(AY24>=1)) | BW24: =IF(OR(AY24=0,BF24<>"Y",BG24<>"Y"),"",1+SUMPRODUCT(($A$6:$A$2604=A24)*($AY$6:$AY$2604>0)*($BF$6:$BF$2604="Y")*($BG$6:$BG$2604="Y")*(($AY$6:$AY$2604>AY24)+($AY$6:$AY$2604=AY24)*($AD$6:$AD$2604>AD24))))
A25: 46296 | B25: ITC | C25: INE154A01025 | D25: Fast Moving Consumer Goods | E25: Nifty 50 | F25: 320656 | G25: N | I25: N | J25: =IF(K25="","N","Y") | K25: =_xlfn.TEXTJOIN("; ",TRUE,IF(P25="52-wk low","52-wk low",""),IF(AND(AD25>=Settings!$B$12,M25<0),"Distribution",""),IF(AND(AJ25="Y",M25<0,AK25<-Settings!$B$13),"Long unwinding",""),IF(AND(AJ25="Y",M25<0,AK25>Settings!$B$13),"Short buildup","")) | L25: 255.9 | M25: -2.61 | N25: 1945 | O25: None | P25: 52-wk low | Q25: 164.47 | R25: 115.34 | S25: 1.44 | T25: 1.17 | U25: 1.11 | V25: 0.78 | W25: 3 | X25: 251 | Y25: None | Z25: 60.19 | AA25: 1.04 | AB25: 1.04 | AC25: 1.49 | AD25: 1.24 | AE25: 1.14 | AF25: 1 | AG25: Normal | AH25: 0 | AI25: 0 | AJ25: Y | AK25: 0.82 | AL25: Short buildup | AM25: 55 | AN25: None | AO25: 0 | AP25: 0.43 | AQ25: 1 | AR25: Y | AS25: 2.11 | AT25: =IF(AND(P25="52-wk high",T25>=Settings!$B$7),"Y","N") | AU25: =IF(AND(AD25>=Settings!$B$8,M25>0),"Y","N") | AV25: =IF(OR(AH25>Settings!$B$9,AI25>Settings!$B$9),"Y","N") | AW25: =IF(AJ25<>"Y","n/a",IF(AND(M25>0,AK25>Settings!$B$10),"Y","N")) | AX25: =IF(AO25>=Settings!$B$11,"Y","N") | AY25: =(AT25="Y")+(AU25="Y")+(AV25="Y")+(AW25="Y")+(AX25="Y") | AZ25: =IF(AY25=0,"None",_xlfn.TEXTJOIN(", ",TRUE(),IF(AT25="Y","Breakout",""),IF(AU25="Y","Accumulation",""),IF(AV25="Y","Institutional buying",""),IF(AW25="Y","Long buildup",""),IF(AX25="Y","Momentum leader",""))) | BA25: =IF(BW25="","","Passes "&AY25&" of 5 buy-side scans"&IF(G25="Y","; RED FLAG: filter out using Red flag column","")) | BB25: None | BC25: N | BF25: =IF(R25*100000>=Settings!$B$5,"Y","N") | BG25: =IF(F25>Settings!$B$6,"Y","N") | BH25: -39.99 | BI25: -4.51 | BJ25: -4.01 | BK25: -11.85 | BL25: -12.27 | BM25: -36.91 | BN25: -3.4 | BO25: -5.41 | BP25: -9.07 | BQ25: -15.92 | BR25: Stacked down | BS25: None | BT25: 31.9 | BU25: N | BV25: =IF(OR(BF25<>"Y",BG25<>"Y"),"",(AND(ISNUMBER(BQ25),BQ25>0))+(BR25="Stacked up")+(AND(ISNUMBER(BH25),BH25>=-Settings!$B$17))+(AND(ISNUMBER(BK25),ISNUMBER(BM25),BK25>0,BM25>0))+(AND(ISNUMBER(AQ25),AQ25>=Settings!$B$18))+(AND(ISNUMBER(BT25),BT25>=Settings!$B$19,BT25<=Settings!$B$20))+(AND(ISNUMBER(AS25),AS25>0))+(AND(ISNUMBER(T25),ISNUMBER(M25),T25>=Settings!$B$21,M25>0))+(AND(ISNUMBER(AD25),ISNUMBER(M25),AD25>=Settings!$B$22,M25>0))+(AY25>=1)) | BW25: =IF(OR(AY25=0,BF25<>"Y",BG25<>"Y"),"",1+SUMPRODUCT(($A$6:$A$2604=A25)*($AY$6:$AY$2604>0)*($BF$6:$BF$2604="Y")*($BG$6:$BG$2604="Y")*(($AY$6:$AY$2604>AY25)+($AY$6:$AY$2604=AY25)*($AD$6:$AD$2604>AD25))))
A26: 46296 | B26: ULTRACEMCO | C26: INE481G01011 | D26: Construction Materials | E26: Nifty 50 | F26: 315601 | G26: N | I26: N | J26: =IF(K26="","N","Y") | K26: =_xlfn.TEXTJOIN("; ",TRUE,IF(P26="52-wk low","52-wk low",""),IF(AND(AD26>=Settings!$B$12,M26<0),"Distribution",""),IF(AND(AJ26="Y",M26<0,AK26<-Settings!$B$13),"Long unwinding",""),IF(AND(AJ26="Y",M26<0,AK26>Settings!$B$13),"Short buildup","")) | L26: 10710 | M26: -2.25 | N26: 1767 | O26: None | P26: None | Q26: 5.71 | R26: 2.99 | S26: 2.03 | T26: 2.18 | U26: 1.95 | V26: 1.01 | W26: 9 | X26: 104 | Y26: None | Z26: 57.14 | AA26: 0.94 | AB26: 0.97 | AC26: 1.92 | AD26: 2.1 | AE26: 1.83 | AF26: 0.99 | AG26: Normal | AH26: 0 | AI26: 0 | AJ26: Y | AK26: 3.56 | AL26: Short buildup | AM26: 68 | AN26: None | AO26: 0 | AP26: 0.69 | AQ26: 36 | AR26: Y | AS26: -0.71 | AT26: =IF(AND(P26="52-wk high",T26>=Settings!$B$7),"Y","N") | AU26: =IF(AND(AD26>=Settings!$B$8,M26>0),"Y","N") | AV26: =IF(OR(AH26>Settings!$B$9,AI26>Settings!$B$9),"Y","N") | AW26: =IF(AJ26<>"Y","n/a",IF(AND(M26>0,AK26>Settings!$B$10),"Y","N")) | AX26: =IF(AO26>=Settings!$B$11,"Y","N") | AY26: =(AT26="Y")+(AU26="Y")+(AV26="Y")+(AW26="Y")+(AX26="Y") | AZ26: =IF(AY26=0,"None",_xlfn.TEXTJOIN(", ",TRUE(),IF(AT26="Y","Breakout",""),IF(AU26="Y","Accumulation",""),IF(AV26="Y","Institutional buying",""),IF(AW26="Y","Long buildup",""),IF(AX26="Y","Momentum leader",""))) | BA26: =IF(BW26="","","Passes "&AY26&" of 5 buy-side scans"&IF(G26="Y","; RED FLAG: filter out using Red flag column","")) | BB26: None | BC26: N | BF26: =IF(R26*100000>=Settings!$B$5,"Y","N") | BG26: =IF(F26>Settings!$B$6,"Y","N") | BH26: -18.31 | BI26: -3.13 | BJ26: -6.05 | BK26: -6.51 | BL26: -0.04 | BM26: -11.45 | BN26: -3.09 | BO26: -5.1 | BP26: -6.45 | BQ26: -7.87 | BR26: Stacked down | BS26: None | BT26: 36.1 | BU26: N | BV26: =IF(OR(BF26<>"Y",BG26<>"Y"),"",(AND(ISNUMBER(BQ26),BQ26>0))+(BR26="Stacked up")+(AND(ISNUMBER(BH26),BH26>=-Settings!$B$17))+(AND(ISNUMBER(BK26),ISNUMBER(BM26),BK26>0,BM26>0))+(AND(ISNUMBER(AQ26),AQ26>=Settings!$B$18))+(AND(ISNUMBER(BT26),BT26>=Settings!$B$19,BT26<=Settings!$B$20))+(AND(ISNUMBER(AS26),AS26>0))+(AND(ISNUMBER(T26),ISNUMBER(M26),T26>=Settings!$B$21,M26>0))+(AND(ISNUMBER(AD26),ISNUMBER(M26),AD26>=Settings!$B$22,M26>0))+(AY26>=1)) | BW26: =IF(OR(AY26=0,BF26<>"Y",BG26<>"Y"),"",1+SUMPRODUCT(($A$6:$A$2604=A26)*($AY$6:$AY$2604>0)*($BF$6:$BF$2604="Y")*($BG$6:$BG$2604="Y")*(($AY$6:$AY$2604>AY26)+($AY$6:$AY$2604=AY26)*($AD$6:$AD$2604>AD26))))
A27: 46296 | B27: NTPC | C27: INE733E01010 | D27: Power | E27: Nifty 50 | F27: 305542 | G27: N | I27: N | J27: =IF(K27="","N","Y") | K27: =_xlfn.TEXTJOIN("; ",TRUE,IF(P27="52-wk low","52-wk low",""),IF(AND(AD27>=Settings!$B$12,M27<0),"Distribution",""),IF(AND(AJ27="Y",M27<0,AK27<-Settings!$B$13),"Long unwinding",""),IF(AND(AJ27="Y",M27<0,AK27>Settings!$B$13),"Short buildup","")) | L27: 315.1 | M27: -2.37 | N27: 1827 | O27: None | P27: 52-wk low | Q27: 100.94 | R27: 75.98 | S27: 1.31 | T27: 1.21 | U27: 0.98 | V27: 0.74 | W27: 3 | Y27: None | Z27: 61.51 | AA27: 0.97 | AB27: 1.01 | AC27: 1.28 | AD27: 1.22 | AE27: 0.97 | AF27: 1.02 | AG27: Normal | AH27: 0 | AI27: 0 | AJ27: Y | AK27: -2.32 | AL27: Long unwinding | AM27: 104 | AN27: 200 Mom 30 | AO27: 1 | AP27: 0.56 | AQ27: 13 | AR27: Y | AS27: 3.38 | AT27: =IF(AND(P27="52-wk high",T27>=Settings!$B$7),"Y","N") | AU27: =IF(AND(AD27>=Settings!$B$8,M27>0),"Y","N") | AV27: =IF(OR(AH27>Settings!$B$9,AI27>Settings!$B$9),"Y","N") | AW27: =IF(AJ27<>"Y","n/a",IF(AND(M27>0,AK27>Settings!$B$10),"Y","N")) | AX27: =IF(AO27>=Settings!$B$11,"Y","N") | AY27: =(AT27="Y")+(AU27="Y")+(AV27="Y")+(AW27="Y")+(AX27="Y") | AZ27: =IF(AY27=0,"None",_xlfn.TEXTJOIN(", ",TRUE(),IF(AT27="Y","Breakout",""),IF(AU27="Y","Accumulation",""),IF(AV27="Y","Institutional buying",""),IF(AW27="Y","Long buildup",""),IF(AX27="Y","Momentum leader",""))) | BA27: =IF(BW27="","","Passes "&AY27&" of 5 buy-side scans"&IF(G27="Y","; RED FLAG: filter out using Red flag column","")) | BB27: None | BC27: N | BF27: =IF(R27*100000>=Settings!$B$5,"Y","N") | BG27: =IF(F27>Settings!$B$6,"Y","N") | BH27: -23.96 | BI27: -3.52 | BJ27: -3.79 | BK27: -11.96 | BL27: -13.59 | BM27: -7.39 | BN27: -3.59 | BO27: -5.93 | BP27: -8.58 | BQ27: -10.12 | BR27: Stacked down | BS27: None | BT27: 25.6 | BU27: N | BV27: =IF(OR(BF27<>"Y",BG27<>"Y"),"",(AND(ISNUMBER(BQ27),BQ27>0))+(BR27="Stacked up")+(AND(ISNUMBER(BH27),BH27>=-Settings!$B$17))+(AND(ISNUMBER(BK27),ISNUMBER(BM27),BK27>0,BM27>0))+(AND(ISNUMBER(AQ27),AQ27>=Settings!$B$18))+(AND(ISNUMBER(BT27),BT27>=Settings!$B$19,BT27<=Settings!$B$20))+(AND(ISNUMBER(AS27),AS27>0))+(AND(ISNUMBER(T27),ISNUMBER(M27),T27>=Settings!$B$21,M27>0))+(AND(ISNUMBER(AD27),ISNUMBER(M27),AD27>=Settings!$B$22,M27>0))+(AY27>=1)) | BW27: =IF(OR(AY27=0,BF27<>"Y",BG27<>"Y"),"",1+SUMPRODUCT(($A$6:$A$2604=A27)*($AY$6:$AY$2604>0)*($BF$6:$BF$2604="Y")*($BG$6:$BG$2604="Y")*(($AY$6:$AY$2604>AY27)+($AY$6:$AY$2604=AY27)*($AD$6:$AD$2604>AD27))))
A28: 46296 | B28: ETERNAL | C28: INE758T01015 | D28: Consumer Services | E28: Nifty 50 | F28: 302925 | G28: N | I28: N | J28: =IF(K28="","N","Y") | K28: =_xlfn.TEXTJOIN("; ",TRUE,IF(P28="52-wk low","52-wk low",""),IF(AND(AD28>=Settings!$B$12,M28<0),"Distribution",""),IF(AND(AJ28="Y",M28<0,AK28<-Settings!$B$13),"Long unwinding",""),IF(AND(AJ28="Y",M28<0,AK28>Settings!$B$13),"Short buildup","")) | L28: 313.9 | M28: -1.91 | N28: 1583 | O28: None | P28: None | Q28: 297.17 | R28: 198.11 | S28: 1.54 | T28: 0.94 | U28: 0.96 | V28: 0.64 | W28: 0 | Y28: By value | Z28: 51.58 | AA28: 0.89 | AB28: 0.93 | AC28: 1.35 | AD28: 0.82 | AE28: 0.88 | AF28: 1.04 | AG28: Normal | AH28: 0 | AI28: 0 | AJ28: Y | AK28: -1.52 | AL28: Long unwinding | AM28: 18 | AN28: None | AO28: 0 | AP28: 1.24 | AQ28: 71 | AR28: Y | AS28: 2.34 | AT28: =IF(AND(P28="52-wk high",T28>=Settings!$B$7),"Y","N") | AU28: =IF(AND(AD28>=Settings!$B$8,M28>0),"Y","N") | AV28: =IF(OR(AH28>Settings!$B$9,AI28>Settings!$B$9),"Y","N") | AW28: =IF(AJ28<>"Y","n/a",IF(AND(M28>0,AK28>Settings!$B$10),"Y","N")) | AX28: =IF(AO28>=Settings!$B$11,"Y","N") | AY28: =(AT28="Y")+(AU28="Y")+(AV28="Y")+(AW28="Y")+(AX28="Y") | AZ28: =IF(AY28=0,"None",_xlfn.TEXTJOIN(", ",TRUE(),IF(AT28="Y","Breakout",""),IF(AU28="Y","Accumulation",""),IF(AV28="Y","Institutional buying",""),IF(AW28="Y","Long buildup",""),IF(AX28="Y","Momentum leader",""))) | BA28: =IF(BW28="","","Passes "&AY28&" of 5 buy-side scans"&IF(G28="Y","; RED FLAG: filter out using Red flag column","")) | BB28: None | BC28: Y | BD28: PE > 50 | BF28: =IF(R28*100000>=Settings!$B$5,"Y","N") | BG28: =IF(F28>Settings!$B$6,"Y","N") | BH28: -14.81 | BI28: -6.44 | BJ28: -4.23 | BK28: 12.23 | BL28: 32.72 | BM28: -4.59 | BN28: -3.75 | BO28: -0.79 | BP28: 4.18 | BQ28: 6.84 | BR28: Mixed | BS28: None | BT28: 31.5 | BU28: N | BV28: =IF(OR(BF28<>"Y",BG28<>"Y"),"",(AND(ISNUMBER(BQ28),BQ28>0))+(BR28="Stacked up")+(AND(ISNUMBER(BH28),BH28>=-Settings!$B$17))+(AND(ISNUMBER(BK28),ISNUMBER(BM28),BK28>0,BM28>0))+(AND(ISNUMBER(AQ28),AQ28>=Settings!$B$18))+(AND(ISNUMBER(BT28),BT28>=Settings!$B$19,BT28<=Settings!$B$20))+(AND(ISNUMBER(AS28),AS28>0))+(AND(ISNUMBER(T28),ISNUMBER(M28),T28>=Settings!$B$21,M28>0))+(AND(ISNUMBER(AD28),ISNUMBER(M28),AD28>=Settings!$B$22,M28>0))+(AY28>=1)) | BW28: =IF(OR(AY28=0,BF28<>"Y",BG28<>"Y"),"",1+SUMPRODUCT(($A$6:$A$2604=A28)*($AY$6:$AY$2604>0)*($BF$6:$BF$2604="Y")*($BG$6:$BG$2604="Y")*(($AY$6:$AY$2604>AY28)+($AY$6:$AY$2604=AY28)*($AD$6:$AD$2604>AD28))))
